Workbook

Sheet US Overview
A1: US FISCAL ACCOUNTING — RAW -> BVAR -> RECURSION -> PROJECTION
A3: THE TARGET CONCEPT
A4: User's level form | B4: B_t = Exp_t - Rev_t + (1 + i_eff_t)*B_{t-1}, then d_t = B_t / GDP_t. Exp = PRIMARY expenditure (EXCLUDES interest). Rev = revenue. i_eff = effective rate on the debt stock. B = debt stock (level). The interest cost sits entirely in the (1+i_eff)*B_{t-1} term. d = B/GDP.
A5: App's ratio form (per quarter) | B5: d_t = d_{t-1}*(1 + i_eff/400)/(1 + gNomQ/100) - pb/4 (% of GDP; i_eff %/yr; gNomQ %/quarter; pb = rev - primexp). This is the user's level form rewritten in ratio space and quarterised - the SAME identity. The 'Fiscal Arithmetic' sheet proves the two land on the identical debt/GDP, column by column.
A7: THE THREE BVAR FISCAL DRIVERS (estimated)
A8: FREV_GDP | B8: Revenue / GDP * 100 (% of GDP). BVAR 'lin' variable.
A9: FPEXP_GDP | B9: (Expenditure - interest) / GDP * 100 = PRIMARY expenditure / GDP (% of GDP). 'lin'.
A10: DSVC | B10: Debt service / GDP * 100 = net interest / LAGGED GDP (% of GDP). 'lin'. THIS is forecast by the BVAR; the effective rate i_eff is BACKED OUT from it as i_eff = DSVC*100 / d_{t-1}.
A11: (internal) EFFI | B11: Effective interest rate = net interest / LAGGED debt stock * 100 (% p.a.). DSVC = EFFI * d_{t-1}/100, i.e. debt service = the effective rate applied to last quarter's debt ratio.
A13: THE FIVE SHEETS PER COUNTRY
A14: Raw Data | B14: the raw series in levels, with charts.
A15: Construction | B15: builds FREV_GDP, FPEXP_GDP, EFFI and DSVC from the raw cells with LIVE formulas.
A16: Fiscal Arithmetic | B16: reconstructs HISTORICAL debt/GDP from the flows (back-cast check vs observed).
A17: Projection | B17: how the BVAR projects DSVC (debt service) and debt/GDP AHEAD, with 16/84 bands.
A19: RAW SERIES & SOURCES
A20: Raw series (role) | B20: Source ID / provenance, units
A21: nominal GDP | B21: FRED: GDP - nominal GDP, $bn SAAR
A22: federal receipts | B22: FRED: FGRECPT - federal current receipts, $bn SAAR
A23: federal expenditure | B23: FRED: FGEXPND - federal current expenditures (INCL. interest), $bn SAAR
A24: federal net interest | B24: FRED: A091RC1Q027SBEA - federal interest payments, $bn SAAR
A25: gross federal debt | B25: FRED: GFDEGDQ188S - gross federal debt as % of GDP (the d0 anchor)
A27: UNIT CONVENTIONS
A28: SAAR (US flows) | B28: GDP/FGRECPT/FGEXPND/A091 are Seasonally-Adjusted ANNUAL RATES: each quarter already states an annual $-rate, so a ratio is flow_t / GDP_t with NO *4.
A29: Quarterly levels (UK flows) | B29: ONS revenue/expenditure/interest are quarterly LEVELS (GBP m, not annualised), so the ratio uses a 4-QUARTER TRAILING SUM: 4q-sum(flow)/4q-sum(GDP).
A30: % of GDP (annual ratio) | B30: FREV_GDP, FPEXP_GDP, DSVC are annual ratios, e.g. 18 means 18% of GDP. Carried in the BVAR as 'lin' (level) variables.
A31: Effective rate | B31: EFFI is %/year on the debt STOCK (e.g. 3 = 3%/yr); NOT the policy or market yield.
A32: Debt / GDP (d) | B32: d, d0 in %, e.g. 100 = 100% of GDP. This workbook's US d0 = 122.5682%.
A33: Nominal growth gNomQ | B33: %/QUARTER. US: from SAAR GDP (already annual). UK: from the 4q-GDP base (same base the ratio uses). The forecast uses Delta(real 100*log GDP) + Delta(deflator 100*log).
A35: COVID NOTE (US only): the deployed BVAR linearly interpolates FPEXP_GDP across the SAME 7 quarters it carries, 2020Q2-2021Q4, to remove the CARES/ARP emergency-spending spike (raw 2020Q2 FPEXP ~42% of GDP vs a ~20% norm). US flows are SAAR, so there is NO annual-window lag: the treated quarters ARE the BVAR's quarters. The Construction sheet shows BOTH the raw (no-COVID) FPEXP and the value that actually entered the BVAR. FREV and DSVC are untreated. The UK gets no COVID treatment (raw == deployed).
A36: SPOT-CHECK vs the deployed BVAR app/public/data/bvar/US: US 2025Q4 (last history): FREV_GDP=18.7715, FPEXP_GDP=20.2281, DSVC=3.9472 - MATCH historical.json cols 33/34/35 exactly. All 40 quarters match to <1e-4, except the 7 COVID quarters 2020Q2-2021Q4 where the into-BVAR FPEXP is interpolated (raw 2020Q2 FPEXP=41.97 vs into-BVAR 20.04). BVAR projects DSVC 3.96 -> 4.92% of GDP over 20 quarters (see US Projection).

Sheet US Raw Data
A1: US RAW DATA - FRED quarterly (SAAR flows; debt as % of GDP)
A3: Date | B3: GDP ($bn, SAAR) | C3: FGRECPT receipts ($bn, SAAR) | D3: FGEXPND expenditure ($bn, SAAR) | E3: A091 net interest ($bn, SAAR) | F3: GFDEGDQ188S gross debt (% of GDP)
B4: FRED: GDP | C4: FRED: FGRECPT | D4: FRED: FGEXPND | E4: FRED: A091RC1Q027SBEA | F4: FRED: GFDEGDQ188S
A5: 1998-Q2 | B5: 8969.699 | C5: 1771.548 | D5: 1781.911 | E5: 367.648 | F5: 61.85196
A6: 1998-Q3 | B6: 9121.097 | C6: 1808.447 | D6: 1788.538 | E6: 366.204 | F6: 60.58693
A7: 1998-Q4 | B7: 9293.991 | C7: 1835.085 | D7: 1814.518 | E7: 360.088 | F7: 60.40696
A8: 1999-Q1 | B8: 9411.682 | C8: 1860.002 | D8: 1811.988 | E8: 352.596 | F8: 60.04894
A9: 1999-Q2 | B9: 9526.21 | C9: 1885.184 | D9: 1816.961 | E9: 352.141 | F9: 59.19227
A10: 1999-Q3 | B10: 9686.626 | C10: 1914.862 | D10: 1843.205 | E10: 351.073 | F10: 58.39258
A11: 1999-Q4 | B11: 9900.169 | C11: 1963.756 | D11: 1875.154 | E11: 352.925 | F11: 58.34336
A12: 2000-Q1 | B12: 10002.179 | C12: 2041.764 | D12: 1866.308 | E12: 354.822 | F12: 57.72134
A13: 2000-Q2 | B13: 10247.72 | C13: 2056.279 | D13: 1908.645 | E13: 354.109 | F13: 55.48491
A14: 2000-Q3 | B14: 10318.165 | C14: 2076.268 | D14: 1918.617 | E14: 352.877 | F14: 54.99213
A15: 2000-Q4 | B15: 10435.744 | C15: 2096.796 | D15: 1938.796 | E15: 353.105 | F15: 54.2579
A16: 2001-Q1 | B16: 10470.231 | C16: 2111.058 | D16: 1982.626 | E16: 345.479 | F16: 55.14434
... A115: 2025-Q4 | B115: 31422.526 | C115: 5898.479 | D115: 7583.663 | E115: 1227.495 | F115: 122.56815

Sheet US Construction
A1: US CONSTRUCTION - BVAR fiscal inputs from raw cells (LIVE FORMULAS)
A2: Every value is a LIVE formula referencing 'US Raw Data'. US flows are SAAR (already annual): ratios are flow_t/GDP_t with NO *4. Lags reference the row ABOVE on Raw Data; the first row here is 1998Q3 (1998Q2 sits on Raw Data only to supply that lag). Column C is the RAW (no-COVID) FPEXP; column D is the FPEXP that ACTUALLY entered the BVAR (= raw, except interpolated across 2020Q2-2021Q4). FREV (B) and DSVC (G) are untreated.
A4: Date | B4: FREV_GDP (% GDP) | C4: FPEXP_GDP RAW (% GDP) | D4: FPEXP_GDP into BVAR (% GDP) | E4: net interest ($bn) | F4: EFFI (% p.a.) | G4: d_{t-1} (% GDP) | H4: DSVC (% GDP)
B5: FREV = FGRECPT / GDP * 100 | C5: raw primary exp = (FGEXPND - A091) / GDP * 100 [no COVID treatment] | D5: = raw, EXCEPT linearly interpolated across 2020Q2-2021Q4 (COVID outlier) | E5: = A091 (SAAR) - the debt-service $ cost | F5: EFFI = A091 / [ (debt/GDP_{t-1}/100) * GDP_{t-1} ] * 100 | G5: = GFDEGDQ188S of the previous quarter (lagged debt ratio) | H5: DSVC = A091 / GDP_{t-1} * 100 = EFFI * d_{t-1}/100 (DEBT SERVICE)
A6: ='US Raw Data'!A6 -> 1998-Q3 | B6: ='US Raw Data'!C6/'US Raw Data'!B6*100 -> 19.827078 | C6: =('US Raw Data'!D6-'US Raw Data'!E6)/'US Raw Data'!B6*100 -> 15.593892 | D6: =C6 -> 15.593892 | E6: ='US Raw Data'!E6 -> 366.204 | F6: ='US Raw Data'!E6/(('US Raw Data'!F5/100)*'US Raw Data'!B5)*100 -> 6.6007266 | G6: ='US Raw Data'!F5 -> 61.85196 | H6: ='US Raw Data'!E6/'US Raw Data'!B5*100 -> 4.0826788
A7: ='US Raw Data'!A7 -> 1998-Q4 | B7: ='US Raw Data'!C7/'US Raw Data'!B7*100 -> 19.744854 | C7: =('US Raw Data'!D7-'US Raw Data'!E7)/'US Raw Data'!B7*100 -> 15.649144 | D7: =C7 -> 15.649144 | E7: ='US Raw Data'!E7 -> 360.088 | F7: ='US Raw Data'!E7/(('US Raw Data'!F6/100)*'US Raw Data'!B6)*100 -> 6.5160233 | G7: ='US Raw Data'!F6 -> 60.58693 | H7: ='US Raw Data'!E7/'US Raw Data'!B6*100 -> 3.9478585
A8: ='US Raw Data'!A8 -> 1999-Q1 | B8: ='US Raw Data'!C8/'US Raw Data'!B8*100 -> 19.762695 | C8: =('US Raw Data'!D8-'US Raw Data'!E8)/'US Raw Data'!B8*100 -> 15.506176 | D8: =C8 -> 15.506176 | E8: ='US Raw Data'!E8 -> 352.596 | F8: ='US Raw Data'!E8/(('US Raw Data'!F7/100)*'US Raw Data'!B7)*100 -> 6.2804123 | G8: ='US Raw Data'!F7 -> 60.40696 | H8: ='US Raw Data'!E8/'US Raw Data'!B7*100 -> 3.7938061
A9: ='US Raw Data'!A9 -> 1999-Q2 | B9: ='US Raw Data'!C9/'US Raw Data'!B9*100 -> 19.789444 | C9: =('US Raw Data'!D9-'US Raw Data'!E9)/'US Raw Data'!B9*100 -> 15.376734 | D9: =C9 -> 15.376734 | E9: ='US Raw Data'!E9 -> 352.141 | F9: ='US Raw Data'!E9/(('US Raw Data'!F8/100)*'US Raw Data'!B8)*100 -> 6.2308027 | G9: ='US Raw Data'!F8 -> 60.04894 | H9: ='US Raw Data'!E9/'US Raw Data'!B8*100 -> 3.741531
A10: ='US Raw Data'!A10 -> 1999-Q3 | B10: ='US Raw Data'!C10/'US Raw Data'!B10*100 -> 19.768101 | C10: =('US Raw Data'!D10-'US Raw Data'!E10)/'US Raw Data'!B10*100 -> 15.404043 | D10: =C10 -> 15.404043 | E10: ='US Raw Data'!E10 -> 351.073 | F10: ='US Raw Data'!E10/(('US Raw Data'!F9/100)*'US Raw Data'!B9)*100 -> 6.2260454 | G10: ='US Raw Data'!F9 -> 59.19227 | H10: ='US Raw Data'!E10/'US Raw Data'!B9*100 -> 3.6853376
A11: ='US Raw Data'!A11 -> 1999-Q4 | B11: ='US Raw Data'!C11/'US Raw Data'!B11*100 -> 19.835581 | C11: =('US Raw Data'!D11-'US Raw Data'!E11)/'US Raw Data'!B11*100 -> 15.375788 | D11: =C11 -> 15.375788 | E11: ='US Raw Data'!E11 -> 352.925 | F11: ='US Raw Data'!E11/(('US Raw Data'!F10/100)*'US Raw Data'!B10)*100 -> 6.239535 | G11: ='US Raw Data'!F10 -> 58.39258 | H11: ='US Raw Data'!E11/'US Raw Data'!B10*100 -> 3.6434255
A12: ='US Raw Data'!A12 -> 2000-Q1 | B12: ='US Raw Data'!C12/'US Raw Data'!B12*100 -> 20.413192 | C12: =('US Raw Data'!D12-'US Raw Data'!E12)/'US Raw Data'!B12*100 -> 15.111567 | D12: =C12 -> 15.111567 | E12: ='US Raw Data'!E12 -> 354.822 | F12: ='US Raw Data'!E12/(('US Raw Data'!F11/100)*'US Raw Data'!B11)*100 -> 6.1429431 | G12: ='US Raw Data'!F11 -> 58.34336 | H12: ='US Raw Data'!E12/'US Raw Data'!B11*100 -> 3.5839994
A13: ='US Raw Data'!A13 -> 2000-Q2 | B13: ='US Raw Data'!C13/'US Raw Data'!B13*100 -> 20.065722 | C13: =('US Raw Data'!D13-'US Raw Data'!E13)/'US Raw Data'!B13*100 -> 15.169579 | D13: =C13 -> 15.169579 | E13: ='US Raw Data'!E13 -> 354.109 | F13: ='US Raw Data'!E13/(('US Raw Data'!F12/100)*'US Raw Data'!B12)*100 -> 6.1334657 | G13: ='US Raw Data'!F12 -> 57.72134 | H13: ='US Raw Data'!E13/'US Raw Data'!B12*100 -> 3.5403186
A14: ='US Raw Data'!A14 -> 2000-Q3 | B14: ='US Raw Data'!C14/'US Raw Data'!B14*100 -> 20.122454 | C14: =('US Raw Data'!D14-'US Raw Data'!E14)/'US Raw Data'!B14*100 -> 15.174597 | D14: =C14 -> 15.174597 | E14: ='US Raw Data'!E14 -> 352.877 | F14: ='US Raw Data'!E14/(('US Raw Data'!F13/100)*'US Raw Data'!B13)*100 -> 6.206135 | G14: ='US Raw Data'!F13 -> 55.48491 | H14: ='US Raw Data'!E14/'US Raw Data'!B13*100 -> 3.4434684
A15: ='US Raw Data'!A15 -> 2000-Q4 | B15: ='US Raw Data'!C15/'US Raw Data'!B15*100 -> 20.092444 | C15: =('US Raw Data'!D15-'US Raw Data'!E15)/'US Raw Data'!B15*100 -> 15.194805 | D15: =C15 -> 15.194805 | E15: ='US Raw Data'!E15 -> 353.105 | F15: ='US Raw Data'!E15/(('US Raw Data'!F14/100)*'US Raw Data'!B14)*100 -> 6.2230151 | G15: ='US Raw Data'!F14 -> 54.99213 | H15: ='US Raw Data'!E15/'US Raw Data'!B14*100 -> 3.4221686
A16: ='US Raw Data'!A16 -> 2001-Q1 | B16: ='US Raw Data'!C16/'US Raw Data'!B16*100 -> 20.162478 | C16: =('US Raw Data'!D16-'US Raw Data'!E16)/'US Raw Data'!B16*100 -> 15.636207 | D16: =C16 -> 15.636207 | E16: ='US Raw Data'!E16 -> 345.479 | F16: ='US Raw Data'!E16/(('US Raw Data'!F15/100)*'US Raw Data'!B15)*100 -> 6.1014809 | G16: ='US Raw Data'!F15 -> 54.2579 | H16: ='US Raw Data'!E16/'US Raw Data'!B15*100 -> 3.3105354
A17: ='US Raw Data'!A17 -> 2001-Q2 | B17: ='US Raw Data'!C17/'US Raw Data'!B17*100 -> 19.797707 | C17: =('US Raw Data'!D17-'US Raw Data'!E17)/'US Raw Data'!B17*100 -> 15.744929 | D17: =C17 -> 15.744929 | E17: ='US Raw Data'!E17 -> 334.776 | F17: ='US Raw Data'!E17/(('US Raw Data'!F16/100)*'US Raw Data'!B16)*100 -> 5.7982523 | G17: ='US Raw Data'!F16 -> 55.14434 | H17: ='US Raw Data'!E17/'US Raw Data'!B16*100 -> 3.197408
... A92: ='US Raw Data'!A92 -> 2020-Q1 | B92: ='US Raw Data'!C92/'US Raw Data'!B92*100 -> 17.429895 | C92: =('US Raw Data'!D92-'US Raw Data'!E92)/'US Raw Data'!B92*100 -> 19.872437 | D92: =C92 -> 19.872437 | E92: ='US Raw Data'!E92 -> 544.122 | F92: ='US Raw Data'!E92/(('US Raw Data'!F91/100)*'US Raw Data'!B91)*100 -> 2.3452139 | G92: ='US Raw Data'!F91 -> 105.78193 | H92: ='US Raw Data'!E92/'US Raw Data'!B91*100 -> 2.4808126
A93: ='US Raw Data'!A93 -> 2020-Q2 | B93: ='US Raw Data'!C93/'US Raw Data'!B93*100 -> 17.709487 | C93: =('US Raw Data'!D93-'US Raw Data'!E93)/'US Raw Data'!B93*100 -> 41.970708 | D93: =C92+(C100-C92)*0.125 -> 20.044705 | E93: ='US Raw Data'!E93 -> 514.737 | F93: ='US Raw Data'!E93/(('US Raw Data'!F92/100)*'US Raw Data'!B92)*100 -> 2.2164191 | G93: ='US Raw Data'!F92 -> 106.77007 | H93: ='US Raw Data'!E93/'US Raw Data'!B92*100 -> 2.3664722
A94: ='US Raw Data'!A94 -> 2020-Q3 | B94: ='US Raw Data'!C94/'US Raw Data'!B94*100 -> 17.496768 | C94: =('US Raw Data'!D94-'US Raw Data'!E94)/'US Raw Data'!B94*100 -> 30.713075 | D94: =C92+(C100-C92)*0.25 -> 20.216974 | E94: ='US Raw Data'!E94 -> 508.011 | F94: ='US Raw Data'!E94/(('US Raw Data'!F93/100)*'US Raw Data'!B93)*100 -> 1.9186704 | G94: ='US Raw Data'!F93 -> 132.66287 | H94: ='US Raw Data'!E94/'US Raw Data'!B93*100 -> 2.5453632
A95: ='US Raw Data'!A95 -> 2020-Q4 | B95: ='US Raw Data'!C95/'US Raw Data'!B95*100 -> 17.853617 | C95: =('US Raw Data'!D95-'US Raw Data'!E95)/'US Raw Data'!B95*100 -> 24.501258 | D95: =C92+(C100-C92)*0.375 -> 20.389243 | E95: ='US Raw Data'!E95 -> 516.711 | F95: ='US Raw Data'!E95/(('US Raw Data'!F94/100)*'US Raw Data'!B94)*100 -> 1.917623 | G95: ='US Raw Data'!F94 -> 124.14692 | H95: ='US Raw Data'!E95/'US Raw Data'!B94*100 -> 2.3806699
A96: ='US Raw Data'!A96 -> 2021-Q1 | B96: ='US Raw Data'!C96/'US Raw Data'!B96*100 -> 18.232873 | C96: =('US Raw Data'!D96-'US Raw Data'!E96)/'US Raw Data'!B96*100 -> 34.4468 | D96: =C92+(C100-C92)*0.5 -> 20.561512 | E96: ='US Raw Data'!E96 -> 533.518 | F96: ='US Raw Data'!E96/(('US Raw Data'!F95/100)*'US Raw Data'!B95)*100 -> 1.9227399 | G96: ='US Raw Data'!F95 -> 125.62864 | H96: ='US Raw Data'!E96/'US Raw Data'!B95*100 -> 2.415512
A97: ='US Raw Data'!A97 -> 2021-Q2 | B97: ='US Raw Data'!C97/'US Raw Data'!B97*100 -> 18.649581 | C97: =('US Raw Data'!D97-'US Raw Data'!E97)/'US Raw Data'!B97*100 -> 30.708267 | D97: =C92+(C100-C92)*0.625 -> 20.733781 | E97: ='US Raw Data'!E97 -> 560.634 | F97: ='US Raw Data'!E97/(('US Raw Data'!F96/100)*'US Raw Data'!B96)*100 -> 1.992829 | G97: ='US Raw Data'!F96 -> 124.03752 | H97: ='US Raw Data'!E97/'US Raw Data'!B96*100 -> 2.4718557
A98: ='US Raw Data'!A98 -> 2021-Q3 | B98: ='US Raw Data'!C98/'US Raw Data'!B98*100 -> 18.860264 | C98: =('US Raw Data'!D98-'US Raw Data'!E98)/'US Raw Data'!B98*100 -> 25.88438 | D98: =C92+(C100-C92)*0.75 -> 20.90605 | E98: ='US Raw Data'!E98 -> 587.92 | F98: ='US Raw Data'!E98/(('US Raw Data'!F97/100)*'US Raw Data'!B97)*100 -> 2.0607487 | G98: ='US Raw Data'!F97 -> 121.78582 | H98: ='US Raw Data'!E98/'US Raw Data'!B97*100 -> 2.5096997
A99: ='US Raw Data'!A99 -> 2021-Q4 | B99: ='US Raw Data'!C99/'US Raw Data'!B99*100 -> 18.89706 | C99: =('US Raw Data'!D99-'US Raw Data'!E99)/'US Raw Data'!B99*100 -> 22.679998 | D99: =C92+(C100-C92)*0.875 -> 21.078318 | E99: ='US Raw Data'!E99 -> 612.282 | F99: ='US Raw Data'!E99/(('US Raw Data'!F98/100)*'US Raw Data'!B98)*100 -> 2.1537295 | G99: ='US Raw Data'!F98 -> 118.54086 | H99: ='US Raw Data'!E99/'US Raw Data'!B98*100 -> 2.5530495
A100: ='US Raw Data'!A100 -> 2022-Q1 | B100: ='US Raw Data'!C100/'US Raw Data'!B100*100 -> 20.099177 | C100: =('US Raw Data'!D100-'US Raw Data'!E100)/'US Raw Data'!B100*100 -> 21.250587 | D100: =C100 -> 21.250587 | E100: ='US Raw Data'!E100 -> 636.968 | F100: ='US Raw Data'!E100/(('US Raw Data'!F99/100)*'US Raw Data'!B99)*100 -> 2.1506681 | G100: ='US Raw Data'!F99 -> 119.3588 | H100: ='US Raw Data'!E100/'US Raw Data'!B99*100 -> 2.5670116
A101: ='US Raw Data'!A101 -> 2022-Q2 | B101: ='US Raw Data'!C101/'US Raw Data'!B101*100 -> 19.85511 | C101: =('US Raw Data'!D101-'US Raw Data'!E101)/'US Raw Data'!B101*100 -> 20.860972 | D101: =C101 -> 20.860972 | E101: ='US Raw Data'!E101 -> 684.758 | F101: ='US Raw Data'!E101/(('US Raw Data'!F100/100)*'US Raw Data'!B100)*100 -> 2.2524222 | G101: ='US Raw Data'!F100 -> 120.39819 | H101: ='US Raw Data'!E101/'US Raw Data'!B100*100 -> 2.7118756
A102: ='US Raw Data'!A102 -> 2022-Q3 | B102: ='US Raw Data'!C102/'US Raw Data'!B102*100 -> 19.552546 | C102: =('US Raw Data'!D102-'US Raw Data'!E102)/'US Raw Data'!B102*100 -> 20.60523 | D102: =C102 -> 20.60523 | E102: ='US Raw Data'!E102 -> 752.081 | F102: ='US Raw Data'!E102/(('US Raw Data'!F101/100)*'US Raw Data'!B101)*100 -> 2.4603071 | G102: ='US Raw Data'!F101 -> 118.20207 | H102: ='US Raw Data'!E102/'US Raw Data'!B101*100 -> 2.9081339
A103: ='US Raw Data'!A103 -> 2022-Q4 | B103: ='US Raw Data'!C103/'US Raw Data'!B103*100 -> 19.061136 | C103: =('US Raw Data'!D103-'US Raw Data'!E103)/'US Raw Data'!B103*100 -> 20.527189 | D103: =C103 -> 20.527189 | E103: ='US Raw Data'!E103 -> 823.106 | F103: ='US Raw Data'!E103/(('US Raw Data'!F102/100)*'US Raw Data'!B102)*100 -> 2.6612833 | G103: ='US Raw Data'!F102 -> 117.43832 | H103: ='US Raw Data'!E103/'US Raw Data'!B102*100 -> 3.1253664
A104: ='US Raw Data'!A104 -> 2023-Q1 | B104: ='US Raw Data'!C104/'US Raw Data'!B104*100 -> 17.460014 | C104: =('US Raw Data'!D104-'US Raw Data'!E104)/'US Raw Data'!B104*100 -> 20.47414 | D104: =C104 -> 20.47414 | E104: ='US Raw Data'!E104 -> 861.267 | F104: ='US Raw Data'!E104/(('US Raw Data'!F103/100)*'US Raw Data'!B103)*100 -> 2.7411696 | G104: ='US Raw Data'!F103 -> 117.36678 | H104: ='US Raw Data'!E104/'US Raw Data'!B103*100 -> 3.2172225
A105: ='US Raw Data'!A105 -> 2023-Q2 | B105: ='US Raw Data'!C105/'US Raw Data'!B105*100 -> 17.324401 | C105: =('US Raw Data'!D105-'US Raw Data'!E105)/'US Raw Data'!B105*100 -> 20.332655 | D105: =C105 -> 20.332655 | E105: ='US Raw Data'!E105 -> 894.106 | F105: ='US Raw Data'!E105/(('US Raw Data'!F104/100)*'US Raw Data'!B104)*100 -> 2.8421818 | G105: ='US Raw Data'!F104 -> 115.58614 | H105: ='US Raw Data'!E105/'US Raw Data'!B104*100 -> 3.2851682
A106: ='US Raw Data'!A106 -> 2023-Q3 | B106: ='US Raw Data'!C106/'US Raw Data'!B106*100 -> 17.22377 | C106: =('US Raw Data'!D106-'US Raw Data'!E106)/'US Raw Data'!B106*100 -> 19.917245 | D106: =C106 -> 19.917245 | E106: ='US Raw Data'!E106 -> 966.899 | F106: ='US Raw Data'!E106/(('US Raw Data'!F105/100)*'US Raw Data'!B105)*100 -> 2.9905073 | G106: ='US Raw Data'!F105 -> 117.44355 | H106: ='US Raw Data'!E106/'US Raw Data'!B105*100 -> 3.5121579
A107: ='US Raw Data'!A107 -> 2023-Q4 | B107: ='US Raw Data'!C107/'US Raw Data'!B107*100 -> 17.331906 | C107: =('US Raw Data'!D107-'US Raw Data'!E107)/'US Raw Data'!B107*100 -> 19.830097 | D107: =C107 -> 19.830097 | E107: ='US Raw Data'!E107 -> 1031.478 | F107: ='US Raw Data'!E107/(('US Raw Data'!F106/100)*'US Raw Data'!B106)*100 -> 3.1099214 | G107: ='US Raw Data'!F106 -> 118.13897 | H107: ='US Raw Data'!E107/'US Raw Data'!B106*100 -> 3.6740291
A108: ='US Raw Data'!A108 -> 2024-Q1 | B108: ='US Raw Data'!C108/'US Raw Data'!B108*100 -> 17.576326 | C108: =('US Raw Data'!D108-'US Raw Data'!E108)/'US Raw Data'!B108*100 -> 20.116053 | D108: =C108 -> 20.116053 | E108: ='US Raw Data'!E108 -> 1071.174 | F108: ='US Raw Data'!E108/(('US Raw Data'!F107/100)*'US Raw Data'!B107)*100 -> 3.1503734 | G108: ='US Raw Data'!F107 -> 119.61944 | H108: ='US Raw Data'!E108/'US Raw Data'!B107*100 -> 3.768459
A109: ='US Raw Data'!A109 -> 2024-Q2 | B109: ='US Raw Data'!C109/'US Raw Data'!B109*100 -> 17.657015 | C109: =('US Raw Data'!D109-'US Raw Data'!E109)/'US Raw Data'!B109*100 -> 20.07221 | D109: =C109 -> 20.07221 | E109: ='US Raw Data'!E109 -> 1103.565 | F109: ='US Raw Data'!E109/(('US Raw Data'!F108/100)*'US Raw Data'!B108)*100 -> 3.1907361 | G109: ='US Raw Data'!F108 -> 120.47631 | H109: ='US Raw Data'!E109/'US Raw Data'!B108*100 -> 3.8440811
A110: ='US Raw Data'!A110 -> 2024-Q3 | B110: ='US Raw Data'!C110/'US Raw Data'!B110*100 -> 17.654426 | C110: =('US Raw Data'!D110-'US Raw Data'!E110)/'US Raw Data'!B110*100 -> 20.396956 | D110: =C110 -> 20.396956 | E110: ='US Raw Data'!E110 -> 1146.182 | F110: ='US Raw Data'!E110/(('US Raw Data'!F109/100)*'US Raw Data'!B109)*100 -> 3.2906353 | G110: ='US Raw Data'!F109 -> 119.50314 | H110: ='US Raw Data'!E110/'US Raw Data'!B109*100 -> 3.9324125
A111: ='US Raw Data'!A111 -> 2024-Q4 | B111: ='US Raw Data'!C111/'US Raw Data'!B111*100 -> 17.814453 | C111: =('US Raw Data'!D111-'US Raw Data'!E111)/'US Raw Data'!B111*100 -> 20.425847 | D111: =C111 -> 20.425847 | E111: ='US Raw Data'!E111 -> 1155.616 | F111: ='US Raw Data'!E111/(('US Raw Data'!F110/100)*'US Raw Data'!B110)*100 -> 3.2584988 | G111: ='US Raw Data'!F110 -> 120.17172 | H111: ='US Raw Data'!E111/'US Raw Data'!B110*100 -> 3.9157941
... A115: ='US Raw Data'!A115 -> 2025-Q4 | B115: ='US Raw Data'!C115/'US Raw Data'!B115*100 -> 18.771499 | C115: =('US Raw Data'!D115-'US Raw Data'!E115)/'US Raw Data'!B115*100 -> 20.228062 | D115: =C115 -> 20.228062 | E115: ='US Raw Data'!E115 -> 1227.495 | F115: ='US Raw Data'!E115/(('US Raw Data'!F114/100)*'US Raw Data'!B114)*100 -> 3.2613571 | G115: ='US Raw Data'!F114 -> 121.02875 | H115: ='US Raw Data'!E115/'US Raw Data'!B114*100 -> 3.9471797

Sheet US Fiscal Arithmetic
A1: US FISCAL ARITHMETIC - decompose the OBSERVED debt/GDP change (LIVE)
A2: A one-step decomposition of the OBSERVED debt change: each row rolls forward from the OBSERVED d_{t-1}, so it is an exact quarter-by-quarter accounting. Same budget identity in two forms: RATIO form (the app): d_t = d_{t-1}*(1+i_eff/400)/(1+gNomQ/100) - pb/4 + sfa/4 LEVEL form (your concept): B_t = (1+i_eff/400)*B_{t-1} - PB$_t + SFA$_t , then d_t = B_t/GDPann_t*100. pb = FREV - FPEXP. SFA (col H) is a COMPUTED residual = the part of the observed debt change NOT explained by interest+growth+primary balance (the deficit-debt discrepancy: valuation, below-the-line financing). It is NOT a zero input - it is informative. With it, BOTH forms reproduce OBSERVED debt/GDP to the last digit (col L = 0).
A4: Date | B4: pb (% GDP) | C4: DSVC = interest (% GDP) | D4: i_eff (% p.a.) | E4: gNomQ (% / quarter) | F4: d_{t-1} OBSERVED (% GDP) | G4: snowball (pp) | H4: SFA (% GDP, residual) | I4: d_t RATIO form (% GDP) | J4: B_t LEVEL ($/GBP) | K4: d_t from LEVEL (% GDP) | L4: OBSERVED d_t (% GDP) | M4: recon - observed (pp)
B5: primary balance = FREV - FPEXP (FPEXP as it ENTERED the BVAR) | C5: debt service from Construction (the estimated driver) | D5: effective rate, BACKED OUT: i_eff = DSVC*100 / d_{t-1} | E5: US: 100*(GDP_t/GDP_{t-1}-1), SAAR. UK: 100*(4qGDP_t/4qGDP_{t-1}-1) | F5: lagged OBSERVED debt ratio (the decomposition starts from data each step) | G5: = [(1+i_eff/400)/(1+gNomQ/100) - 1] * d_{t-1} (automatic debt dynamics) | H5: = 4*(d_obs_t - d_{t-1} - snowball + pb/4) (deficit-debt discrepancy, COMPUTED) | I5: = d_{t-1}(1+i_eff/400)/(1+gNomQ/100) - pb/4 + sfa/4 | J5: = (1+i_eff/400)*B_{t-1} - PB$_t + SFA$_t ; B_{t-1}=d_{t-1}/100*GDPann_{t-1} | K5: = B_t / GDPann_t * 100 (must equal the RATIO-form d_t) | L5: US: GFDEGDQ188S; UK: 100*gross_debt_t/4qGDP_t (back-cast TARGET) | M5: = d_t(ratio) - observed (the CHECK, ~0 with the SFA residual)
A6: ='US Construction'!A6 -> 1998-Q3 | B6: ='US Construction'!B6-'US Construction'!D6 -> 4.233186 | C6: ='US Construction'!H6 -> 4.0826788 | D6: =C6*100/F6 -> 6.7385471 | E6: =100*('US Raw Data'!B6/'US Raw Data'!B5-1) -> 1.6878827 | F6: ='US Raw Data'!F6 -> 60.58693 | G6: =((1+D6/400)/(1+E6/100)-1)*F6 -> -0.001933981 | H6: =4*(L6-F6-G6+B6/4) -> 4.2409219 | I6: =F6*(1+D6/400)/(1+E6/100)-B6/4+H6/4 -> 60.58693 | J6: =(1+D6/400)*(F6/100*'US Raw Data'!B5)-B6/100*'US Raw Data'!B6/4+H6/100*'US Raw Data'!B6/4 -> 5526.1927 | K6: =J6/'US Raw Data'!B6*100 -> 60.58693 | L6: ='US Raw Data'!F6 -> 60.58693 | M6: =I6-L6 -> 0
A7: ='US Construction'!A7 -> 1998-Q4 | B7: ='US Construction'!B7-'US Construction'!D7 -> 4.0957109 | C7: ='US Construction'!H7 -> 3.9478585 | D7: =C7*100/F7 -> 6.5160233 | E7: =100*('US Raw Data'!B7/'US Raw Data'!B6-1) -> 1.8955395 | F7: ='US Raw Data'!F6 -> 60.58693 | G7: =((1+D7/400)/(1+E7/100)-1)*F7 -> -0.15848054 | H7: =4*(L7-F7-G7+B7/4) -> 4.009753 | I7: =F7*(1+D7/400)/(1+E7/100)-B7/4+H7/4 -> 60.40696 | J7: =(1+D7/400)*(F7/100*'US Raw Data'!B6)-B7/100*'US Raw Data'!B7/4+H7/100*'US Raw Data'!B7/4 -> 5614.2174 | K7: =J7/'US Raw Data'!B7*100 -> 60.40696 | L7: ='US Raw Data'!F7 -> 60.40696 | M7: =I7-L7 -> 0
A8: ='US Construction'!A8 -> 1999-Q1 | B8: ='US Construction'!B8-'US Construction'!D8 -> 4.2565187 | C8: ='US Construction'!H8 -> 3.7938061 | D8: =C8*100/F8 -> 6.2804123 | E8: =100*('US Raw Data'!B8/'US Raw Data'!B7-1) -> 1.2663128 | F8: ='US Raw Data'!F7 -> 60.40696 | G8: =((1+D8/400)/(1+E8/100)-1)*F8 -> 0.18121569 | H8: =4*(L8-F8-G8+B8/4) -> 2.0995759 | I8: =F8*(1+D8/400)/(1+E8/100)-B8/4+H8/4 -> 60.04894 | J8: =(1+D8/400)*(F8/100*'US Raw Data'!B7)-B8/100*'US Raw Data'!B8/4+H8/100*'US Raw Data'!B8/4 -> 5651.6153 | K8: =J8/'US Raw Data'!B8*100 -> 60.04894 | L8: ='US Raw Data'!F8 -> 60.04894 | M8: =I8-L8 -> 0
A9: ='US Construction'!A9 -> 1999-Q2 | B9: ='US Construction'!B9-'US Construction'!D9 -> 4.4127098 | C9: ='US Construction'!H9 -> 3.741531 | D9: =C9*100/F9 -> 6.2308027 | E9: =100*('US Raw Data'!B9/'US Raw Data'!B8-1) -> 1.2168707 | F9: ='US Raw Data'!F8 -> 60.04894 | G9: =((1+D9/400)/(1+E9/100)-1)*F9 -> 0.20220423 | H9: =4*(L9-F9-G9+B9/4) -> 0.17721284 | I9: =F9*(1+D9/400)/(1+E9/100)-B9/4+H9/4 -> 59.19227 | J9: =(1+D9/400)*(F9/100*'US Raw Data'!B8)-B9/100*'US Raw Data'!B9/4+H9/100*'US Raw Data'!B9/4 -> 5638.7799 | K9: =J9/'US Raw Data'!B9*100 -> 59.19227 | L9: ='US Raw Data'!F9 -> 59.19227 | M9: =I9-L9 -> 0
A10: ='US Construction'!A10 -> 1999-Q3 | B10: ='US Construction'!B10-'US Construction'!D10 -> 4.3640582 | C10: ='US Construction'!H10 -> 3.6853376 | D10: =C10*100/F10 -> 6.2260454 | E10: =100*('US Raw Data'!B10/'US Raw Data'!B9-1) -> 1.6839436 | F10: ='US Raw Data'!F9 -> 59.19227 | G10: =((1+D10/400)/(1+E10/100)-1)*F10 -> -0.074180854 | H10: =4*(L10-F10-G10+B10/4) -> 1.4620217 | I10: =F10*(1+D10/400)/(1+E10/100)-B10/4+H10/4 -> 58.39258 | J10: =(1+D10/400)*(F10/100*'US Raw Data'!B9)-B10/100*'US Raw Data'!B10/4+H10/100*'US Raw Data'!B10/4 -> 5656.2708 | K10: =J10/'US Raw Data'!B10*100 -> 58.39258 | L10: ='US Raw Data'!F10 -> 58.39258 | M10: =I10-L10 -> 0
A11: ='US Construction'!A11 -> 1999-Q4 | B11: ='US Construction'!B11-'US Construction'!D11 -> 4.4597926 | C11: ='US Construction'!H11 -> 3.6434255 | D11: =C11*100/F11 -> 6.239535 | E11: =100*('US Raw Data'!B11/'US Raw Data'!B10-1) -> 2.2045137 | F11: ='US Raw Data'!F10 -> 58.39258 | G11: =((1+D11/400)/(1+E11/100)-1)*F11 -> -0.36829692 | H11: =4*(L11-F11-G11+B11/4) -> 5.7361002 | I11: =F11*(1+D11/400)/(1+E11/100)-B11/4+H11/4 -> 58.34336 | J11: =(1+D11/400)*(F11/100*'US Raw Data'!B10)-B11/100*'US Raw Data'!B11/4+H11/100*'US Raw Data'!B11/4 -> 5776.0912 | K11: =J11/'US Raw Data'!B11*100 -> 58.34336 | L11: ='US Raw Data'!F11 -> 58.34336 | M11: =I11-L11 -> 0
A12: ='US Construction'!A12 -> 2000-Q1 | B12: ='US Construction'!B12-'US Construction'!D12 -> 5.3016248 | C12: ='US Construction'!H12 -> 3.5839994 | D12: =C12*100/F12 -> 6.1429431 | E12: =100*('US Raw Data'!B12/'US Raw Data'!B11-1) -> 1.0303865 | F12: ='US Raw Data'!F11 -> 58.34336 | G12: =((1+D12/400)/(1+E12/100)-1)*F12 -> 0.29183079 | H12: =4*(L12-F12-G12+B12/4) -> 1.6462216 | I12: =F12*(1+D12/400)/(1+E12/100)-B12/4+H12/4 -> 57.72134 | J12: =(1+D12/400)*(F12/100*'US Raw Data'!B11)-B12/100*'US Raw Data'!B12/4+H12/100*'US Raw Data'!B12/4 -> 5773.3917 | K12: =J12/'US Raw Data'!B12*100 -> 57.72134 | L12: ='US Raw Data'!F12 -> 57.72134 | M12: =I12-L12 -> 0
A13: ='US Construction'!A13 -> 2000-Q2 | B13: ='US Construction'!B13-'US Construction'!D13 -> 4.8961428 | C13: ='US Construction'!H13 -> 3.5403186 | D13: =C13*100/F13 -> 6.1334657 | E13: =100*('US Raw Data'!B13/'US Raw Data'!B12-1) -> 2.4548751 | F13: ='US Raw Data'!F12 -> 57.72134 | G13: =((1+D13/400)/(1+E13/100)-1)*F13 -> -0.51916236 | H13: =4*(L13-F13-G13+B13/4) -> -1.9729278 | I13: =F13*(1+D13/400)/(1+E13/100)-B13/4+H13/4 -> 55.48491 | J13: =(1+D13/400)*(F13/100*'US Raw Data'!B12)-B13/100*'US Raw Data'!B13/4+H13/100*'US Raw Data'!B13/4 -> 5685.9382 | K13: =J13/'US Raw Data'!B13*100 -> 55.48491 | L13: ='US Raw Data'!F13 -> 55.48491 | M13: =I13-L13 -> 0
A14: ='US Construction'!A14 -> 2000-Q3 | B14: ='US Construction'!B14-'US Construction'!D14 -> 4.9478565 | C14: ='US Construction'!H14 -> 3.4434684 | D14: =C14*100/F14 -> 6.206135 | E14: =100*('US Raw Data'!B14/'US Raw Data'!B13-1) -> 0.6874212 | F14: ='US Raw Data'!F13 -> 55.48491 | G14: =((1+D14/400)/(1+E14/100)-1)*F14 -> 0.47617871 | H14: =4*(L14-F14-G14+B14/4) -> 1.0720217 | I14: =F14*(1+D14/400)/(1+E14/100)-B14/4+H14/4 -> 54.99213 | J14: =(1+D14/400)*(F14/100*'US Raw Data'!B13)-B14/100*'US Raw Data'!B14/4+H14/100*'US Raw Data'!B14/4 -> 5674.1787 | K14: =J14/'US Raw Data'!B14*100 -> 54.99213 | L14: ='US Raw Data'!F14 -> 54.99213 | M14: =I14-L14 -> 0
A15: ='US Construction'!A15 -> 2000-Q4 | B15: ='US Construction'!B15-'US Construction'!D15 -> 4.8976383 | C15: ='US Construction'!H15 -> 3.4221686 | D15: =C15*100/F15 -> 6.2230151 | E15: =100*('US Raw Data'!B15/'US Raw Data'!B14-1) -> 1.139534 | F15: ='US Raw Data'!F14 -> 54.99213 | G15: =((1+D15/400)/(1+E15/100)-1)*F15 -> 0.22630925 | H15: =4*(L15-F15-G15+B15/4) -> 1.0554814 | I15: =F15*(1+D15/400)/(1+E15/100)-B15/4+H15/4 -> 54.2579 | J15: =(1+D15/400)*(F15/100*'US Raw Data'!B14)-B15/100*'US Raw Data'!B15/4+H15/100*'US Raw Data'!B15/4 -> 5662.2155 | K15: =J15/'US Raw Data'!B15*100 -> 54.2579 | L15: ='US Raw Data'!F15 -> 54.2579 | M15: =I15-L15 -> 0
A16: ='US Construction'!A16 -> 2001-Q1 | B16: ='US Construction'!B16-'US Construction'!D16 -> 4.5262707 | C16: ='US Construction'!H16 -> 3.3105354 | D16: =C16*100/F16 -> 6.1014809 | E16: =100*('US Raw Data'!B16/'US Raw Data'!B15-1) -> 0.33046997 | F16: ='US Raw Data'!F15 -> 54.2579 | G16: =((1+D16/400)/(1+E16/100)-1)*F16 -> 0.64619231 | H16: =4*(L16-F16-G16+B16/4) -> 5.4872615 | I16: =F16*(1+D16/400)/(1+E16/100)-B16/4+H16/4 -> 55.14434 | J16: =(1+D16/400)*(F16/100*'US Raw Data'!B15)-B16/100*'US Raw Data'!B16/4+H16/100*'US Raw Data'!B16/4 -> 5773.7398 | K16: =J16/'US Raw Data'!B16*100 -> 55.14434 | L16: ='US Raw Data'!F16 -> 55.14434 | M16: =I16-L16 -> 0
A17: ='US Construction'!A17 -> 2001-Q2 | B17: ='US Construction'!B17-'US Construction'!D17 -> 4.0527786 | C17: ='US Construction'!H17 -> 3.197408 | D17: =C17*100/F17 -> 5.7982523 | E17: =100*('US Raw Data'!B17/'US Raw Data'!B16-1) -> 1.2298583 | F17: ='US Raw Data'!F16 -> 55.14434 | G17: =((1+D17/400)/(1+E17/100)-1)*F17 -> 0.11968285 | H17: =4*(L17-F17-G17+B17/4) -> -0.87671282 | I17: =F17*(1+D17/400)/(1+E17/100)-B17/4+H17/4 -> 54.03165 | J17: =(1+D17/400)*(F17/100*'US Raw Data'!B16)-B17/100*'US Raw Data'!B17/4+H17/100*'US Raw Data'!B17/4 -> 5726.8146 | K17: =J17/'US Raw Data'!B17*100 -> 54.03165 | L17: ='US Raw Data'!F17 -> 54.03165 | M17: =I17-L17 -> 0
A18: ='US Construction'!A18 -> 2001-Q3 | B18: ='US Construction'!B18-'US Construction'!D18 -> 1.8569695 | C18: ='US Construction'!H18 -> 3.0835551 | D18: =C18*100/F18 -> 5.7069422 | E18: =100*('US Raw Data'!B18/'US Raw Data'!B17-1) -> -0.0092461553 | F18: ='US Raw Data'!F17 -> 54.03165 | G18: =((1+D18/400)/(1+E18/100)-1)*F18 -> 0.77595636 | H18: =4*(L18-F18-G18+B18/4) -> 1.8170641 | I18: =F18*(1+D18/400)/(1+E18/100)-B18/4+H18/4 -> 54.79763 | J18: =(1+D18/400)*(F18/100*'US Raw Data'!B17)-B18/100*'US Raw Data'!B18/4+H18/100*'US Raw Data'!B18/4 -> 5807.4638 | K18: =J18/'US Raw Data'!B18*100 -> 54.79763 | L18: ='US Raw Data'!F18 -> 54.79763 | M18: =I18-L18 -> 0
... A115: ='US Construction'!A115 -> 2025-Q4 | B115: ='US Construction'!B115-'US Construction'!D115 -> -1.4565634 | C115: ='US Construction'!H115 -> 3.9471797 | D115: =C115*100/F115 -> 3.2613571 | E115: =100*('US Raw Data'!B115/'US Raw Data'!B114-1) -> 1.0434713 | F115: ='US Raw Data'!F114 -> 121.02875 | G115: =((1+D115/400)/(1+E115/100)-1)*F115 -> -0.27325408 | H115: =4*(L115-F115-G115+B115/4) -> 5.794053 | I115: =F115*(1+D115/400)/(1+E115/100)-B115/4+H115/4 -> 122.56815 | J115: =(1+D115/400)*(F115/100*'US Raw Data'!B114)-B115/100*'US Raw Data'!B115/4+H115/100*'US Raw Data'!B115/4 -> 38514.009 | K115: =J115/'US Raw Data'!B115*100 -> 122.56815 | L115: ='US Raw Data'!F115 -> 122.56815 | M115: =I115-L115 -> 0
A117: EQUIVALENCE: the RATIO-form d_t (col I) and the LEVEL-form d_t (col K) are identical to display precision - your level recursion B_t=(1+i_eff)B_{t-1}-(Exp-Rev)+SFA and the app's ratio recursion are the SAME identity. col M (recon - observed) is ~0 because the SFA residual (col H) closes the identity onto observed. SFA itself is the informative deficit-debt discrepancy (financial transactions / valuation / below-the-line) - read it as a column in its own right.

Sheet US Projection
A1: US PROJECTION - how the BVAR forecasts debt service & debt/GDP AHEAD
A2: The orange columns (FREV, FPEXP, DSVC and its 16/84 bands, plus the forecast 100*log GDP and deflator) ARE the deployed BVAR output, app/public/data/bvar/US/baseline_levels.json, over the 20-quarter forecast starting the quarter after the last history. The BVAR forecasts DSVC (debt service) DIRECTLY as a 'lin' variable. From it the white columns back out the effective rate and roll the debt forward with LIVE formulas, exactly as fiscalAccounting.ts does: i_eff = DSVC*100/d_{t-1} ; gNomQ = Delta(100*log GDP) + Delta(100*log deflator) ; pb = FREV - FPEXP ; d_t = d_{t-1}*(1+i_eff/400)/(1+gNomQ/100) - pb/4. The debt-service $ cost = DSVC/100 * GDP grows as both DSVC (the rate*stock effect) and GDP rise. The 16/84 DSVC band shows the BVAR's forecast uncertainty on the debt-service cost.
A4: Fcst q | B4: FREV_GDP (% GDP) | C4: FPEXP_GDP (% GDP) | D4: DSVC (% GDP) | E4: DSVC q16 (% GDP) | F4: DSVC q84 (% GDP) | G4: 100*log GDP | H4: 100*log deflator | I4: gNomQ (% / q) | J4: pb (% GDP) | K4: i_eff (% p.a.) | L4: d_{t-1} (% GDP) | M4: d_t (% GDP)
B5: BVAR forecast, baseline_levels | C5: BVAR forecast, baseline_levels | D5: BVAR forecast debt service (the estimated driver) | E5: BVAR 16th pctile band | F5: BVAR 84th pctile band | G5: BVAR forecast real GDP (level space) | H5: BVAR forecast GDP deflator (level space) | I5: = Delta(100*log GDP) + Delta(100*log deflator) (nominal growth) | J5: = FREV - FPEXP (primary balance) | K5: = DSVC*100 / d_{t-1} (effective rate, backed out) | L5: lagged debt ratio (seed = d0 = last observed debt/GDP) | M5: = d_{t-1}(1+i_eff/400)/(1+gNomQ/100) - pb/4 (PROJECTED debt/GDP)
A6: f+1 | B6: 19.032 | C6: 20.4829 | D6: 3.95743 | E6: 3.91915 | F6: 3.99384 | G6: 1009.17 | H6: 488.191 | I6: =(G6-1008.81)+(H6-487.232) -> 1.319 | J6: =B6-C6 -> -1.4509 | K6: =D6*100/L6 -> 3.2287589 | L6: =122.56815 -> 122.56815 | M6: =L6*(1+K6/400)/(1+I6/100)-J6/4 -> 122.31173
A7: f+2 | B7: 19.1393 | C7: 20.4896 | D7: 3.94955 | E7: 3.88195 | F7: 4.01306 | G7: 1009.66 | H7: 489.238 | I7: =(G7-G6)+(H7-H6) -> 1.537 | J7: =B7-C7 -> -1.3503 | K7: =D7*100/L7 -> 3.2290854 | L7: =M6 -> 122.31173 | M7: =L7*(1+K7/400)/(1+I7/100)-J7/4 -> 121.77027
A8: f+3 | B8: 19.2987 | C8: 20.5015 | D8: 3.95681 | E8: 3.85117 | F8: 4.05111 | G8: 1010.13 | H8: 490.231 | I8: =(G8-G7)+(H8-H7) -> 1.463 | J8: =B8-C8 -> -1.2028 | K8: =D8*100/L8 -> 3.2494057 | L8: =M7 -> 121.77027 | M8: =L8*(1+K8/400)/(1+I8/100)-J8/4 -> 121.29009
A9: f+4 | B9: 19.3462 | C9: 20.5424 | D9: 3.9784 | E9: 3.83564 | F9: 4.10417 | G9: 1010.65 | H9: 491.186 | I9: =(G9-G8)+(H9-H8) -> 1.475 | J9: =B9-C9 -> -1.1962 | K9: =D9*100/L9 -> 3.28007 | L9: =M8 -> 121.29009 | M9: =L9*(1+K9/400)/(1+I9/100)-J9/4 -> 120.80626
A10: f+5 | B10: 19.4201 | C10: 20.5436 | D10: 4.01202 | E10: 3.82215 | F10: 4.18203 | G10: 1011.23 | H10: 492.136 | I10: =(G10-G9)+(H10-H9) -> 1.53 | J10: =B10-C10 -> -1.1235 | K10: =D10*100/L10 -> 3.3210364 | L10: =M9 -> 120.80626 | M10: =L10*(1+K10/400)/(1+I10/100)-J10/4 -> 120.25455
A11: f+6 | B11: 19.4969 | C11: 20.4949 | D11: 4.05644 | E11: 3.81616 | F11: 4.25917 | G11: 1011.87 | H11: 493.102 | I11: =(G11-G10)+(H11-H10) -> 1.606 | J11: =B11-C11 -> -0.998 | K11: =D11*100/L11 -> 3.3732113 | L11: =M10 -> 120.25455 | M11: =L11*(1+K11/400)/(1+I11/100)-J11/4 -> 119.60137
A12: f+7 | B12: 19.5799 | C12: 20.3888 | D12: 4.1093 | E12: 3.84083 | F12: 4.34629 | G12: 1012.59 | H12: 494.082 | I12: =(G12-G11)+(H12-H11) -> 1.7 | J12: =B12-C12 -> -0.8089 | K12: =D12*100/L12 -> 3.4358303 | L12: =M11 -> 119.60137 | M12: =L12*(1+K12/400)/(1+I12/100)-J12/4 -> 118.81451
A13: f+8 | B13: 19.675 | C13: 20.2493 | D13: 4.16857 | E13: 3.86257 | F13: 4.43066 | G13: 1013.37 | H13: 495.071 | I13: =(G13-G12)+(H13-H12) -> 1.769 | J13: =B13-C13 -> -0.5743 | K13: =D13*100/L13 -> 3.5084689 | L13: =M12 -> 118.81451 | M13: =L13*(1+K13/400)/(1+I13/100)-J13/4 -> 117.91682
A14: f+9 | B14: 19.775 | C14: 20.0845 | D14: 4.23208 | E14: 3.88557 | F14: 4.5319 | G14: 1014.21 | H14: 496.074 | I14: =(G14-G13)+(H14-H13) -> 1.843 | J14: =B14-C14 -> -0.3095 | K14: =D14*100/L14 -> 3.5890386 | L14: =M13 -> 117.91682 | M14: =L14*(1+K14/400)/(1+I14/100)-J14/4 -> 116.89918
A15: f+10 | B15: 19.9 | C15: 19.8898 | D15: 4.2981 | E15: 3.89286 | F15: 4.63641 | G15: 1015.09 | H15: 497.09 | I15: =(G15-G14)+(H15-H14) -> 1.896 | J15: =B15-C15 -> 0.0102 | K15: =D15*100/L15 -> 3.6767579 | L15: =M14 -> 116.89918 | M15: =L15*(1+K15/400)/(1+I15/100)-J15/4 -> 115.776
A16: f+11 | B16: 20.0469 | C16: 19.6704 | D16: 4.3654 | E16: 3.90904 | F16: 4.74161 | G16: 1016.01 | H16: 498.122 | I16: =(G16-G15)+(H16-H15) -> 1.952 | J16: =B16-C16 -> 0.3765 | K16: =D16*100/L16 -> 3.770557 | L16: =M15 -> 115.776 | M16: =L16*(1+K16/400)/(1+I16/100)-J16/4 -> 114.53565
A17: f+12 | B17: 20.2121 | C17: 19.4332 | D17: 4.43274 | E17: 3.94096 | F17: 4.85809 | G17: 1016.96 | H17: 499.168 | I17: =(G17-G16)+(H17-H16) -> 1.996 | J17: =B17-C17 -> 0.7789 | K17: =D17*100/L17 -> 3.8701837 | L17: =M16 -> 114.53565 | M17: =L17*(1+K17/400)/(1+I17/100)-J17/4 -> 113.18603
A18: f+13 | B18: 20.3919 | C18: 19.1834 | D18: 4.49947 | E18: 3.96408 | F18: 4.99296 | G18: 1017.92 | H18: 500.229 | I18: =(G18-G17)+(H18-H17) -> 2.021 | J18: =B18-C18 -> 1.2085 | K18: =D18*100/L18 -> 3.9752874 | L18: =M17 -> 113.18603 | M18: =L18*(1+K18/400)/(1+I18/100)-J18/4 -> 111.74431
... A25: f+20 | B25: 21.6321 | C25: 17.4488 | D25: 4.92276 | E25: 4.02741 | F25: 5.73599 | G25: 1024.53 | H25: 507.918 | I25: =(G25-G24)+(H25-H24) -> 2.04 | J25: =B25-C25 -> 4.1833 | K25: =D25*100/L25 -> 4.8440811 | L25: =M24 -> 101.62423 | M25: =L25*(1+K25/400)/(1+I25/100)-J25/4 -> 99.752801
A27: READ-OFF: DSVC (col D) is the BVAR's projected debt-service-to-GDP; the q16/q84 columns are its forecast band. The effective rate i_eff (col K) is what that debt service implies on the rolling debt stock, and the projected debt/GDP (col M) is the budget identity applied forward from d0. This is the exact path the app charts.

Sheet UK Overview
A1: UK FISCAL ACCOUNTING — RAW -> BVAR -> RECURSION -> PROJECTION
A3: THE TARGET CONCEPT
A4: User's level form | B4: B_t = Exp_t - Rev_t + (1 + i_eff_t)*B_{t-1}, then d_t = B_t / GDP_t. Exp = PRIMARY expenditure (EXCLUDES interest). Rev = revenue. i_eff = effective rate on the debt stock. B = debt stock (level). The interest cost sits entirely in the (1+i_eff)*B_{t-1} term. d = B/GDP.
A5: App's ratio form (per quarter) | B5: d_t = d_{t-1}*(1 + i_eff/400)/(1 + gNomQ/100) - pb/4 (% of GDP; i_eff %/yr; gNomQ %/quarter; pb = rev - primexp). This is the user's level form rewritten in ratio space and quarterised - the SAME identity. The 'Fiscal Arithmetic' sheet proves the two land on the identical debt/GDP, column by column.
A7: THE THREE BVAR FISCAL DRIVERS (estimated)
A8: FREV_GDP | B8: Revenue / GDP * 100 (% of GDP). BVAR 'lin' variable.
A9: FPEXP_GDP | B9: (Expenditure - interest) / GDP * 100 = PRIMARY expenditure / GDP (% of GDP). 'lin'.
A10: DSVC | B10: Debt service / GDP * 100 = net interest / LAGGED GDP (% of GDP). 'lin'. THIS is forecast by the BVAR; the effective rate i_eff is BACKED OUT from it as i_eff = DSVC*100 / d_{t-1}.
A11: (internal) EFFI | B11: Effective interest rate = net interest / LAGGED debt stock * 100 (% p.a.). DSVC = EFFI * d_{t-1}/100, i.e. debt service = the effective rate applied to last quarter's debt ratio.
A13: THE FIVE SHEETS PER COUNTRY
A14: Raw Data | B14: the raw series in levels, with charts.
A15: Construction | B15: builds FREV_GDP, FPEXP_GDP, EFFI and DSVC from the raw cells with LIVE formulas.
A16: Fiscal Arithmetic | B16: reconstructs HISTORICAL debt/GDP from the flows (back-cast check vs observed).
A17: Projection | B17: how the BVAR projects DSVC (debt service) and debt/GDP AHEAD, with 16/84 bands.
A19: RAW SERIES & SOURCES
A20: Raw series (role) | B20: Source ID / provenance, units
A21: public-sector revenue | B21: ONS: public-sector current receipts, GBPm quarterly LEVEL
A22: total managed expenditure | B22: ONS: total public-sector expenditure INCL. interest, GBPm quarterly LEVEL
A23: public-sector debt interest | B23: ONS: net public-sector debt interest, GBPm quarterly LEVEL
A24: gross debt stock | B24: ONS: public-sector gross debt, GBPm end-quarter STOCK
A25: nominal GDP | B25: ONS: nominal GDP, GBPm quarterly LEVEL
A27: UNIT CONVENTIONS
A28: SAAR (US flows) | B28: GDP/FGRECPT/FGEXPND/A091 are Seasonally-Adjusted ANNUAL RATES: each quarter already states an annual $-rate, so a ratio is flow_t / GDP_t with NO *4.
A29: Quarterly levels (UK flows) | B29: ONS revenue/expenditure/interest are quarterly LEVELS (GBP m, not annualised), so the ratio uses a 4-QUARTER TRAILING SUM: 4q-sum(flow)/4q-sum(GDP).
A30: % of GDP (annual ratio) | B30: FREV_GDP, FPEXP_GDP, DSVC are annual ratios, e.g. 18 means 18% of GDP. Carried in the BVAR as 'lin' (level) variables.
A31: Effective rate | B31: EFFI is %/year on the debt STOCK (e.g. 3 = 3%/yr); NOT the policy or market yield.
A32: Debt / GDP (d) | B32: d, d0 in %, e.g. 100 = 100% of GDP. This workbook's UK d0 = 96.2412%.
A33: Nominal growth gNomQ | B33: %/QUARTER. US: from SAAR GDP (already annual). UK: from the 4q-GDP base (same base the ratio uses). The forecast uses Delta(real 100*log GDP) + Delta(deflator 100*log).
A35: SPOT-CHECK vs the deployed BVAR app/public/data/bvar/UK: UK 2025Q4 (last history): FREV_GDP=39.4124, FPEXP_GDP=37.6083, DSVC=3.8142, d0=96.2412 - MATCH historical.json cols 16/17/18 and fiscal_meta.json exactly. All 40 quarters match to <1e-4. No COVID treatment applied. BVAR projects DSVC 4.21 -> 3.31% of GDP over 20 quarters (see UK Projection).

Sheet UK Raw Data
A1: UK RAW DATA - ONS quarterly LEVELS (GBP million, not annualised)
A3: Date | B3: revenue (GBPm, q-level) | C3: total_expenditure (GBPm) | D3: interest (GBPm, q-level) | E3: gross_debt (GBPm, stock) | F3: nominal_gdp (GBPm, q-level)
B4: ONS public-sector current receipts | C4: ONS total managed expenditure (incl. interest) | D4: ONS public-sector debt interest (net) | E4: ONS public-sector gross debt (end-quarter STOCK) | F4: ONS nominal GDP, quarterly level
A5: 2000-Q1 | B5: 106101 | C5: 88583 | D5: 7941 | E5: 353300 | F5: 273551
A6: 2000-Q2 | B6: 97108 | C6: 87401 | D6: 8806 | E6: 341800 | F6: 275103
A7: 2000-Q3 | B7: 101376 | C7: 90818 | D7: 8408 | E7: 326600 | F7: 277076
A8: 2000-Q4 | B8: 95606 | C8: 93164 | D8: 9090 | E8: 333300 | F8: 279029
A9: 2001-Q1 | B9: 112322 | C9: 94677 | D9: 8353 | E9: 322000 | F9: 283724
A10: 2001-Q2 | B10: 99956 | C10: 94300 | D10: 8130 | E10: 330300 | F10: 287603
A11: 2001-Q3 | B11: 103742 | C11: 95848 | D11: 7608 | E11: 324600 | F11: 289333
A12: 2001-Q4 | B12: 96971 | C12: 100049 | D12: 8185 | E12: 335500 | F12: 289882
A13: 2002-Q1 | B13: 111742 | C13: 102469 | D13: 7375 | E13: 330600 | F13: 293878
A14: 2002-Q2 | B14: 99718 | C14: 102328 | D14: 8018 | E14: 339100 | F14: 297001
A15: 2002-Q3 | B15: 105076 | C15: 104237 | D15: 6825 | E15: 343600 | F15: 299863
A16: 2002-Q4 | B16: 99790 | C16: 106936 | D16: 8443 | E16: 368700 | F16: 303904
... A108: 2025-Q4 | B108: 294399 | C108: 314524 | D108: 28690 | E108: 2925600 | F108: 769261

Sheet UK Construction
A1: UK CONSTRUCTION - BVAR fiscal inputs from raw cells (LIVE FORMULAS, 4q trailing sums)
A2: UK flows are quarterly LEVELS, so each ratio annualises via a 4-QUARTER TRAILING SUM (SUM over the current and prior 3 rows; the first few rows use the available <4 quarters, matching the pipeline). EFFI uses *4 (a quarterly interest vs a stock); contrast the US, already SAAR. The UK gets NO COVID treatment: raw == what enters the BVAR.
A4: Date | B4: 4q rev | C4: 4q primexp | D4: 4q GDP | E4: FREV_GDP (% GDP) | F4: FPEXP_GDP (% GDP) | G4: EFFI (% p.a.) | H4: d_t (% GDP) | I4: d_{t-1} (% GDP) | J4: DSVC (% GDP)
B5: = SUM(revenue, this + prior 3 q) | C5: = SUM(total_exp - interest, this + prior 3 q) | D5: = SUM(nominal_gdp, this + prior 3 q) | E5: FREV = 100 * 4qRev / 4qGDP | F5: FPEXP = 100 * 4qPrimexp / 4qGDP | G5: EFFI = 100 * 4 * interest_t / gross_debt_{t-1} | H5: d = 100 * gross_debt_t / 4qGDP_t | I5: = prior-row d_t (lagged debt ratio) | J5: DSVC = EFFI * d_{t-1}/100 = 100*4*interest_t/4qGDP_{t-1} (DEBT SERVICE)
A6: ='UK Raw Data'!A5 -> 2000-Q1 | B6: =SUM('UK Raw Data'!B5:B5) -> 106101 | C6: =SUM('UK Raw Data'!C5:C5)-SUM('UK Raw Data'!D5:D5) -> 80642 | D6: =SUM('UK Raw Data'!F5:F5) -> 273551 | E6: =100*B6/D6 -> 38.786552 | F6: =100*C6/D6 -> 29.479695 | G6: =100*4*'UK Raw Data'!D5/'UK Raw Data'!E5 -> 8.9906595 | H6: =100*'UK Raw Data'!E5/D6 -> 129.15325 | I6: =H6 -> 129.15325 | J6: =G6*I6/100 -> 11.611729
A7: ='UK Raw Data'!A6 -> 2000-Q2 | B7: =SUM('UK Raw Data'!B5:B6) -> 203209 | C7: =SUM('UK Raw Data'!C5:C6)-SUM('UK Raw Data'!D5:D6) -> 159237 | D7: =SUM('UK Raw Data'!F5:F6) -> 548654 | E7: =100*B7/D7 -> 37.037732 | F7: =100*C7/D7 -> 29.02321 | G7: =100*4*'UK Raw Data'!D6/'UK Raw Data'!E5 -> 9.9699972 | H7: =100*'UK Raw Data'!E6/D7 -> 62.297915 | I7: =H6 -> 129.15325 | J7: =G7*I7/100 -> 12.876575
A8: ='UK Raw Data'!A7 -> 2000-Q3 | B8: =SUM('UK Raw Data'!B5:B7) -> 304585 | C8: =SUM('UK Raw Data'!C5:C7)-SUM('UK Raw Data'!D5:D7) -> 241647 | D8: =SUM('UK Raw Data'!F5:F7) -> 825730 | E8: =100*B8/D8 -> 36.886755 | F8: =100*C8/D8 -> 29.264651 | G8: =100*4*'UK Raw Data'!D7/'UK Raw Data'!E6 -> 9.8396723 | H8: =100*'UK Raw Data'!E7/D8 -> 39.55288 | I8: =H7 -> 62.297915 | J8: =G8*I8/100 -> 6.1299107
A9: ='UK Raw Data'!A8 -> 2000-Q4 | B9: =SUM('UK Raw Data'!B5:B8) -> 400191 | C9: =SUM('UK Raw Data'!C5:C8)-SUM('UK Raw Data'!D5:D8) -> 325721 | D9: =SUM('UK Raw Data'!F5:F8) -> 1104759 | E9: =100*B9/D9 -> 36.224281 | F9: =100*C9/D9 -> 29.483444 | G9: =100*4*'UK Raw Data'!D8/'UK Raw Data'!E7 -> 11.132884 | H9: =100*'UK Raw Data'!E8/D9 -> 30.169476 | I9: =H8 -> 39.55288 | J9: =G9*I9/100 -> 4.4033764
A10: ='UK Raw Data'!A9 -> 2001-Q1 | B10: =SUM('UK Raw Data'!B6:B9) -> 406412 | C10: =SUM('UK Raw Data'!C6:C9)-SUM('UK Raw Data'!D6:D9) -> 331403 | D10: =SUM('UK Raw Data'!F6:F9) -> 1114932 | E10: =100*B10/D10 -> 36.45173 | F10: =100*C10/D10 -> 29.724055 | G10: =100*4*'UK Raw Data'!D9/'UK Raw Data'!E8 -> 10.024602 | H10: =100*'UK Raw Data'!E9/D10 -> 28.880685 | I10: =H9 -> 30.169476 | J10: =G10*I10/100 -> 3.02437
A11: ='UK Raw Data'!A10 -> 2001-Q2 | B11: =SUM('UK Raw Data'!B7:B10) -> 409260 | C11: =SUM('UK Raw Data'!C7:C10)-SUM('UK Raw Data'!D7:D10) -> 338978 | D11: =SUM('UK Raw Data'!F7:F10) -> 1127432 | E11: =100*B11/D11 -> 36.300194 | F11: =100*C11/D11 -> 30.066381 | G11: =100*4*'UK Raw Data'!D10/'UK Raw Data'!E9 -> 10.099379 | H11: =100*'UK Raw Data'!E10/D11 -> 29.296667 | I11: =H10 -> 28.880685 | J11: =G11*I11/100 -> 2.9167698
A12: ='UK Raw Data'!A11 -> 2001-Q3 | B12: =SUM('UK Raw Data'!B8:B11) -> 411626 | C12: =SUM('UK Raw Data'!C8:C11)-SUM('UK Raw Data'!D8:D11) -> 344808 | D12: =SUM('UK Raw Data'!F8:F11) -> 1139689 | E12: =100*B12/D12 -> 36.117397 | F12: =100*C12/D12 -> 30.254569 | G12: =100*4*'UK Raw Data'!D11/'UK Raw Data'!E10 -> 9.2134423 | H12: =100*'UK Raw Data'!E11/D12 -> 28.481454 | I12: =H11 -> 29.296667 | J12: =G12*I12/100 -> 2.6992315
A13: ='UK Raw Data'!A12 -> 2001-Q4 | B13: =SUM('UK Raw Data'!B9:B12) -> 412991 | C13: =SUM('UK Raw Data'!C9:C12)-SUM('UK Raw Data'!D9:D12) -> 352598 | D13: =SUM('UK Raw Data'!F9:F12) -> 1150542 | E13: =100*B13/D13 -> 35.895343 | F13: =100*C13/D13 -> 30.646252 | G13: =100*4*'UK Raw Data'!D12/'UK Raw Data'!E11 -> 10.08626 | H13: =100*'UK Raw Data'!E12/D13 -> 29.16017 | I13: =H12 -> 28.481454 | J13: =G13*I13/100 -> 2.8727135
A14: ='UK Raw Data'!A13 -> 2002-Q1 | B14: =SUM('UK Raw Data'!B10:B13) -> 412411 | C14: =SUM('UK Raw Data'!C10:C13)-SUM('UK Raw Data'!D10:D13) -> 361368 | D14: =SUM('UK Raw Data'!F10:F13) -> 1160696 | E14: =100*B14/D14 -> 35.531354 | F14: =100*C14/D14 -> 31.133734 | G14: =100*4*'UK Raw Data'!D13/'UK Raw Data'!E12 -> 8.7928465 | H14: =100*'UK Raw Data'!E13/D14 -> 28.48291 | I14: =H13 -> 29.16017 | J14: =G14*I14/100 -> 2.564009
A15: ='UK Raw Data'!A14 -> 2002-Q2 | B15: =SUM('UK Raw Data'!B11:B14) -> 412173 | C15: =SUM('UK Raw Data'!C11:C14)-SUM('UK Raw Data'!D11:D14) -> 369508 | D15: =SUM('UK Raw Data'!F11:F14) -> 1170094 | E15: =100*B15/D15 -> 35.225631 | F15: =100*C15/D15 -> 31.579343 | G15: =100*4*'UK Raw Data'!D14/'UK Raw Data'!E13 -> 9.7011494 | H15: =100*'UK Raw Data'!E14/D15 -> 28.980578 | I15: =H14 -> 28.48291 | J15: =G15*I15/100 -> 2.7631697
A16: ='UK Raw Data'!A15 -> 2002-Q3 | B16: =SUM('UK Raw Data'!B12:B15) -> 413507 | C16: =SUM('UK Raw Data'!C12:C15)-SUM('UK Raw Data'!D12:D15) -> 378680 | D16: =SUM('UK Raw Data'!F12:F15) -> 1180624 | E16: =100*B16/D16 -> 35.024445 | F16: =100*C16/D16 -> 32.074564 | G16: =100*4*'UK Raw Data'!D15/'UK Raw Data'!E14 -> 8.0507225 | H16: =100*'UK Raw Data'!E15/D16 -> 29.103254 | I16: =H15 -> 28.980578 | J16: =G16*I16/100 -> 2.3331459
A17: ='UK Raw Data'!A16 -> 2002-Q4 | B17: =SUM('UK Raw Data'!B13:B16) -> 416326 | C17: =SUM('UK Raw Data'!C13:C16)-SUM('UK Raw Data'!D13:D16) -> 385309 | D17: =SUM('UK Raw Data'!F13:F16) -> 1194646 | E17: =100*B17/D17 -> 34.849319 | F17: =100*C17/D17 -> 32.252985 | G17: =100*4*'UK Raw Data'!D16/'UK Raw Data'!E15 -> 9.8288708 | H17: =100*'UK Raw Data'!E16/D17 -> 30.862699 | I17: =H16 -> 29.103254 | J17: =G17*I17/100 -> 2.8605212
A18: ='UK Raw Data'!A17 -> 2003-Q1 | B18: =SUM('UK Raw Data'!B14:B17) -> 417783 | C18: =SUM('UK Raw Data'!C14:C17)-SUM('UK Raw Data'!D14:D17) -> 395165 | D18: =SUM('UK Raw Data'!F14:F17) -> 1208344 | E18: =100*B18/D18 -> 34.57484 | F18: =100*C18/D18 -> 32.703022 | G18: =100*4*'UK Raw Data'!D17/'UK Raw Data'!E16 -> 8.040141 | H18: =100*'UK Raw Data'!E17/D18 -> 30.554213 | I18: =H17 -> 30.862699 | J18: =G18*I18/100 -> 2.4814045
A19: ='UK Raw Data'!A18 -> 2003-Q2 | B19: =SUM('UK Raw Data'!B15:B18) -> 424791 | C19: =SUM('UK Raw Data'!C15:C18)-SUM('UK Raw Data'!D15:D18) -> 406087 | D19: =SUM('UK Raw Data'!F15:F18) -> 1224966 | E19: =100*B19/D19 -> 34.677779 | F19: =100*C19/D19 -> 33.150879 | G19: =100*4*'UK Raw Data'!D18/'UK Raw Data'!E17 -> 9.0747562 | H19: =100*'UK Raw Data'!E18/D19 -> 30.653912 | I19: =H18 -> 30.554213 | J19: =G19*I19/100 -> 2.7727204
A20: ='UK Raw Data'!A19 -> 2003-Q3 | B20: =SUM('UK Raw Data'!B16:B19) -> 430638 | C20: =SUM('UK Raw Data'!C16:C19)-SUM('UK Raw Data'!D16:D19) -> 416756 | D20: =SUM('UK Raw Data'!F16:F19) -> 1243978 | E20: =100*B20/D20 -> 34.617815 | F20: =100*C20/D20 -> 33.501879 | G20: =100*4*'UK Raw Data'!D19/'UK Raw Data'!E18 -> 8.1523302 | H20: =100*'UK Raw Data'!E19/D20 -> 30.820481 | I20: =H19 -> 30.653912 | J20: =G20*I20/100 -> 2.4990081
... A109: ='UK Raw Data'!A108 -> 2025-Q4 | B109: =SUM('UK Raw Data'!B105:B108) -> 1198083 | C109: =SUM('UK Raw Data'!C105:C108)-SUM('UK Raw Data'!D105:D108) -> 1143241 | D109: =SUM('UK Raw Data'!F105:F108) -> 3039861 | E109: =100*B109/D109 -> 39.412427 | F109: =100*C109/D109 -> 37.608331 | G109: =100*4*'UK Raw Data'!D108/'UK Raw Data'!E107 -> 3.9390403 | H109: =100*'UK Raw Data'!E108/D109 -> 96.241243 | I109: =H108 -> 96.831586 | J109: =G109*I109/100 -> 3.8142352

Sheet UK Fiscal Arithmetic
A1: UK FISCAL ARITHMETIC - decompose the OBSERVED debt/GDP change (LIVE)
A2: A one-step decomposition of the OBSERVED debt change: each row rolls forward from the OBSERVED d_{t-1}, so it is an exact quarter-by-quarter accounting. Same budget identity in two forms: RATIO form (the app): d_t = d_{t-1}*(1+i_eff/400)/(1+gNomQ/100) - pb/4 + sfa/4 LEVEL form (your concept): B_t = (1+i_eff/400)*B_{t-1} - PB$_t + SFA$_t , then d_t = B_t/GDPann_t*100. pb = FREV - FPEXP. SFA (col H) is a COMPUTED residual = the part of the observed debt change NOT explained by interest+growth+primary balance (the deficit-debt discrepancy: valuation, below-the-line financing). It is NOT a zero input - it is informative. With it, BOTH forms reproduce OBSERVED debt/GDP to the last digit (col L = 0).
A4: Date | B4: pb (% GDP) | C4: DSVC = interest (% GDP) | D4: i_eff (% p.a.) | E4: gNomQ (% / quarter) | F4: d_{t-1} OBSERVED (% GDP) | G4: snowball (pp) | H4: SFA (% GDP, residual) | I4: d_t RATIO form (% GDP) | J4: B_t LEVEL ($/GBP) | K4: d_t from LEVEL (% GDP) | L4: OBSERVED d_t (% GDP) | M4: recon - observed (pp)
B5: primary balance = FREV - FPEXP (FPEXP as it ENTERED the BVAR) | C5: debt service from Construction (the estimated driver) | D5: effective rate, BACKED OUT: i_eff = DSVC*100 / d_{t-1} | E5: US: 100*(GDP_t/GDP_{t-1}-1), SAAR. UK: 100*(4qGDP_t/4qGDP_{t-1}-1) | F5: lagged OBSERVED debt ratio (the decomposition starts from data each step) | G5: = [(1+i_eff/400)/(1+gNomQ/100) - 1] * d_{t-1} (automatic debt dynamics) | H5: = 4*(d_obs_t - d_{t-1} - snowball + pb/4) (deficit-debt discrepancy, COMPUTED) | I5: = d_{t-1}(1+i_eff/400)/(1+gNomQ/100) - pb/4 + sfa/4 | J5: = (1+i_eff/400)*B_{t-1} - PB$_t + SFA$_t ; B_{t-1}=d_{t-1}/100*GDPann_{t-1} | K5: = B_t / GDPann_t * 100 (must equal the RATIO-form d_t) | L5: US: GFDEGDQ188S; UK: 100*gross_debt_t/4qGDP_t (back-cast TARGET) | M5: = d_t(ratio) - observed (the CHECK, ~0 with the SFA residual)
A6: ='UK Construction'!A6 -> 2000-Q1 | B6: ='UK Construction'!E6-'UK Construction'!F6 -> 9.3068569 | C6: ='UK Construction'!J6 -> 11.611729 | D6: =C6*100/F6 -> 8.9906595 | E6: =0 -> 0 | F6: ='UK Construction'!H6 -> 129.15325 | G6: =((1+D6/400)/(1+E6/100)-1)*F6 -> 2.9029322 | H6: =4*(L6-F6-G6+B6/4) -> -2.3048719 | I6: =F6*(1+D6/400)/(1+E6/100)-B6/4+H6/4 -> 129.15325 | J6: =(1+D6/400)*(F6/100*'UK Construction'!D6)-B6/100*'UK Construction'!D6/4+H6/100*'UK Construction'!D6/4 -> 353300 | K6: =J6/'UK Construction'!D6*100 -> 129.15325 | L6: ='UK Construction'!H6 -> 129.15325 | M6: =I6-L6 -> 0
A7: ='UK Construction'!A7 -> 2000-Q2 | B7: ='UK Construction'!E7-'UK Construction'!F7 -> 8.0145228 | C7: ='UK Construction'!J7 -> 12.876575 | D7: =C7*100/F7 -> 9.9699972 | E7: =100*('UK Construction'!D7/'UK Construction'!D6-1) -> 100.56735 | F7: ='UK Construction'!H6 -> 129.15325 | G7: =((1+D7/400)/(1+E7/100)-1)*F7 -> -63.154275 | H7: =4*(L7-F7-G7+B7/4) -> -6.7897072 | I7: =F7*(1+D7/400)/(1+E7/100)-B7/4+H7/4 -> 62.297915 | J7: =(1+D7/400)*(F7/100*'UK Construction'!D6)-B7/100*'UK Construction'!D7/4+H7/100*'UK Construction'!D7/4 -> 341800 | K7: =J7/'UK Construction'!D7*100 -> 62.297915 | L7: ='UK Construction'!H7 -> 62.297915 | M7: =I7-L7 -> 0
A8: ='UK Construction'!A8 -> 2000-Q3 | B8: ='UK Construction'!E8-'UK Construction'!F8 -> 7.6221041 | C8: ='UK Construction'!J8 -> 6.1299107 | D8: =C8*100/F8 -> 9.8396723 | E8: =100*('UK Construction'!D8/'UK Construction'!D7-1) -> 50.501044 | F8: ='UK Construction'!H7 -> 62.297915 | G8: =((1+D8/400)/(1+E8/100)-1)*F8 -> -19.885988 | H8: =4*(L8-F8-G8+B8/4) -> -3.8140797 | I8: =F8*(1+D8/400)/(1+E8/100)-B8/4+H8/4 -> 39.55288 | J8: =(1+D8/400)*(F8/100*'UK Construction'!D7)-B8/100*'UK Construction'!D8/4+H8/100*'UK Construction'!D8/4 -> 326600 | K8: =J8/'UK Construction'!D8*100 -> 39.55288 | L8: ='UK Construction'!H8 -> 39.55288 | M8: =I8-L8 -> 0
A9: ='UK Construction'!A9 -> 2000-Q4 | B9: ='UK Construction'!E9-'UK Construction'!F9 -> 6.7408367 | C9: ='UK Construction'!J9 -> 4.4033764 | D9: =C9*100/F9 -> 11.132884 | E9: =100*('UK Construction'!D9/'UK Construction'!D8-1) -> 33.791796 | F9: ='UK Construction'!H8 -> 39.55288 | G9: =((1+D9/400)/(1+E9/100)-1)*F9 -> -9.1670678 | H9: =4*(L9-F9-G9+B9/4) -> 5.8754896 | I9: =F9*(1+D9/400)/(1+E9/100)-B9/4+H9/4 -> 30.169476 | J9: =(1+D9/400)*(F9/100*'UK Construction'!D8)-B9/100*'UK Construction'!D9/4+H9/100*'UK Construction'!D9/4 -> 333300 | K9: =J9/'UK Construction'!D9*100 -> 30.169476 | L9: ='UK Construction'!H9 -> 30.169476 | M9: =I9-L9 -> 0
A10: ='UK Construction'!A10 -> 2001-Q1 | B10: ='UK Construction'!E10-'UK Construction'!F10 -> 6.7276749 | C10: ='UK Construction'!J10 -> 3.02437 | D10: =C10*100/F10 -> 10.024602 | E10: =100*('UK Construction'!D10/'UK Construction'!D9-1) -> 0.92083432 | F10: ='UK Construction'!H9 -> 30.169476 | G10: =((1+D10/400)/(1+E10/100)-1)*F10 -> 0.47391762 | H10: =4*(L10-F10-G10+B10/4) -> -0.32315872 | I10: =F10*(1+D10/400)/(1+E10/100)-B10/4+H10/4 -> 28.880685 | J10: =(1+D10/400)*(F10/100*'UK Construction'!D9)-B10/100*'UK Construction'!D10/4+H10/100*'UK Construction'!D10/4 -> 322000 | K10: =J10/'UK Construction'!D10*100 -> 28.880685 | L10: ='UK Construction'!H10 -> 28.880685 | M10: =I10-L10 -> 0
A11: ='UK Construction'!A11 -> 2001-Q2 | B11: ='UK Construction'!E11-'UK Construction'!F11 -> 6.2338128 | C11: ='UK Construction'!J11 -> 2.9167698 | D11: =C11*100/F11 -> 10.099379 | E11: =100*('UK Construction'!D11/'UK Construction'!D10-1) -> 1.1211446 | F11: ='UK Construction'!H10 -> 28.880685 | G11: =((1+D11/400)/(1+E11/100)-1)*F11 -> 0.4009035 | H11: =4*(L11-F11-G11+B11/4) -> 6.2941268 | I11: =F11*(1+D11/400)/(1+E11/100)-B11/4+H11/4 -> 29.296667 | J11: =(1+D11/400)*(F11/100*'UK Construction'!D10)-B11/100*'UK Construction'!D11/4+H11/100*'UK Construction'!D11/4 -> 330300 | K11: =J11/'UK Construction'!D11*100 -> 29.296667 | L11: ='UK Construction'!H11 -> 29.296667 | M11: =I11-L11 -> 0
A12: ='UK Construction'!A12 -> 2001-Q3 | B12: ='UK Construction'!E12-'UK Construction'!F12 -> 5.8628275 | C12: ='UK Construction'!J12 -> 2.6992315 | D12: =C12*100/F12 -> 9.2134423 | E12: =100*('UK Construction'!D12/'UK Construction'!D11-1) -> 1.0871609 | F12: ='UK Construction'!H11 -> 29.296667 | G12: =((1+D12/400)/(1+E12/100)-1)*F12 -> 0.35247401 | H12: =4*(L12-F12-G12+B12/4) -> 1.1920796 | I12: =F12*(1+D12/400)/(1+E12/100)-B12/4+H12/4 -> 28.481454 | J12: =(1+D12/400)*(F12/100*'UK Construction'!D11)-B12/100*'UK Construction'!D12/4+H12/100*'UK Construction'!D12/4 -> 324600 | K12: =J12/'UK Construction'!D12*100 -> 28.481454 | L12: ='UK Construction'!H12 -> 28.481454 | M12: =I12-L12 -> 0
A13: ='UK Construction'!A13 -> 2001-Q4 | B13: ='UK Construction'!E13-'UK Construction'!F13 -> 5.2490913 | C13: ='UK Construction'!J13 -> 2.8727135 | D13: =C13*100/F13 -> 10.08626 | E13: =100*('UK Construction'!D13/'UK Construction'!D12-1) -> 0.95227733 | F13: ='UK Construction'!H12 -> 28.481454 | G13: =((1+D13/400)/(1+E13/100)-1)*F13 -> 0.44273984 | H13: =4*(L13-F13-G13+B13/4) -> 6.1929943 | I13: =F13*(1+D13/400)/(1+E13/100)-B13/4+H13/4 -> 29.16017 | J13: =(1+D13/400)*(F13/100*'UK Construction'!D12)-B13/100*'UK Construction'!D13/4+H13/100*'UK Construction'!D13/4 -> 335500 | K13: =J13/'UK Construction'!D13*100 -> 29.16017 | L13: ='UK Construction'!H13 -> 29.16017 | M13: =I13-L13 -> 0
A14: ='UK Construction'!A14 -> 2002-Q1 | B14: ='UK Construction'!E14-'UK Construction'!F14 -> 4.39762 | C14: ='UK Construction'!J14 -> 2.564009 | D14: =C14*100/F14 -> 8.7928465 | E14: =100*('UK Construction'!D14/'UK Construction'!D13-1) -> 0.88254058 | F14: ='UK Construction'!H13 -> 29.16017 | G14: =((1+D14/400)/(1+E14/100)-1)*F14 -> 0.38029565 | H14: =4*(L14-F14-G14+B14/4) -> 0.16739956 | I14: =F14*(1+D14/400)/(1+E14/100)-B14/4+H14/4 -> 28.48291 | J14: =(1+D14/400)*(F14/100*'UK Construction'!D13)-B14/100*'UK Construction'!D14/4+H14/100*'UK Construction'!D14/4 -> 330600 | K14: =J14/'UK Construction'!D14*100 -> 28.48291 | L14: ='UK Construction'!H14 -> 28.48291 | M14: =I14-L14 -> 0
